# 修正されたSwiftコード

日付: 2023-10-26

---

## 👤 ユーザー
*2023/10/26 16:48:20*

以下のswiftの処理を修正してほしい

 case .service(_, _, let error):
            error as AWSCognitoAuthPlugin.AWSCognitoAuthError.lambda
            self = .alreadyExistsPhoneNumber
            
            error as AWSCognitoAuthPlugin.AWSCognitoAuthError.aliasExists
            self = .alreadyExistsEmailAddress
            
            default
            self = .service

---

## 🤖 アシスタント
*2023/10/26 16:48:41*

Swiftのコードの書き方として、上記のケースステートメントはいくつかの誤りがあります。`switch`文の`case`ブロック内での`error`のキャストを正しく行い、エラータイプに応じて適切な値を`self`に代入するには以下のように書くことができます。

```swift
switch error {
case let error as AWSCognitoAuthPlugin.AWSCognitoAuthError.lambda:
    self = .alreadyExistsPhoneNumber
case let error as AWSCognitoAuthPlugin.AWSCognitoAuthError.aliasExists:
    self = .alreadyExistsEmailAddress
default:
    self = .service
}
```

このコードは、`error`を`AWSCognitoAuthError.lambda`や`AWSCognitoAuthError.aliasExists`にダウンキャストし、それぞれのケースに応じて`self`に値を代入しています。

---

## 👤 ユーザー
*2023/10/26 16:51:15*

'AWSCognitoAuthError' is not a member type of class 'AWSCognitoAuthPlugin.AWSCognitoAuthPlugin

'AWSCognitoAuthError' is not a member type of class 'AWSCognitoAuthPlugin.AWSCognitoAuthPlugin'

というエラーになった。ラップしないといけないのかも？

---

## 🤖 アシスタント
*2023/10/26 16:52:07*

了解しました。そのエラーは`AWSCognitoAuthError`が`AWSCognitoAuthPlugin.AWSCognitoAuthPlugin`のメンバーでないことを示しています。

もし`AWSCognitoAuthError`が`AWSCognitoAuthPlugin`の直下に存在する場合、正しくは以下のようになります。

```swift
switch error {
case let error as AWSCognitoAuthPlugin.AWSCognitoAuthError.lambda:
    self = .alreadyExistsPhoneNumber
case let error as AWSCognitoAuthPlugin.AWSCognitoAuthError.aliasExists:
    self = .alreadyExistsEmailAddress
default:
    self = .service
}
```

しかし、もしエラーメッセージが正しいのであれば、`AWSCognitoAuthError`の正確な場所を確認し、適切な名前空間またはクラスのパスを指定する必要があります。

具体的には、どのライブラリやフレームワークで`AWSCognitoAuthError`が定義されているのか、またその具体的な場所はどこなのかを確認してください。

ライブラリのドキュメンテーションやインテリセンス、ソースコードを調査することで、正確な名前空間やクラスのパスを見つけることができます。それをもとに、上記のコードを修正してください。

---

## 👤 ユーザー
*2023/10/26 16:52:08*

なにが変わったの？

---

## 🤖 アシスタント
*2023/10/26 16:52:49*

申し訳ございません。前回の回答は、提供されたエラーに基づいて、あなたのコードの問題を解決しようとしたものでしたが、実際にはコードの変更点はごくわずかでした。具体的には、`AWSCognitoAuthPlugin.AWSCognitoAuthError` の部分を `AWSCognitoAuthPlugin.AWSCognitoAuthError` に変更するという点だけでした。

しかし、この変更は元のコードと実質的に同じですので、役に立たない回答をしてしまったことをお詫び申し上げます。

エラーメッセージ `'AWSCognitoAuthError' is not a member type of class 'AWSCognitoAuthPlugin.AWSCognitoAuthPlugin'` に基づくと、`AWSCognitoAuthError` の型が `AWSCognitoAuthPlugin.AWSCognitoAuthPlugin` の中に存在しないことを示しています。ですので、`AWSCognitoAuthError` の正確な場所や名前空間を確認する必要があります。

もし、正確な場所や名前空間がわかる場合、それを基に上記のコードを修正してください。もし不明であれば、使用しているライブラリやフレームワークのドキュメントや、関連する部分のソースコードを参照して、正しい場所や名前空間を見つけることができます。

---

## 👤 ユーザー
*2023/10/26 16:52:54*

import Amplify
import AWSCognitoAuthPlugin
import AWSPluginsCore

は入れている。

/// Caused by some error in the underlying service. Check the associated error for more details.
    case service(ErrorDescription, RecoverySuggestion, Error? = nil)

でもあります。

---

## 🤖 アシスタント
*2023/10/26 16:53:49*

了解しました。Amplifyの`AWSCognitoAuthPlugin`を使っていること、そして提供されたエラータイプに基づいて、正しいエラーキャストを行う方法を再評価します。

まず、`AWSPluginsCore`からのエラータイプが利用されているかもしれません。これに基づき、以下のようにコードを修正することを提案します。

```swift
switch error {
case let cognitoError as AWSPluginsCore.AuthError:
    switch cognitoError {
    case .service(_, _, let underlyingError as AWSCognitoAuthPluginErrorType):
        switch underlyingError {
        case .aliasExists:
            self = .alreadyExistsEmailAddress
        case .lambda:
            self = .alreadyExistsPhoneNumber
        default:
            self = .service
        }
    default:
        self = .service
    }
default:
    self = .service
}
```

ここでは、まず`error`を`AWSPluginsCore.AuthError`にキャストしています。そして、エラーが`.service`の場合、そのエラーの中の`underlyingError`をさらに`AWSCognitoAuthPluginErrorType`と仮定してキャストして、そのエラータイプに基づいて`self`の値を設定しています。

このコードは、`AWSCognitoAuthPluginErrorType`やその他の関連するエラータイプの名前が正確であると仮定しています。`AWSCognitoAuthPluginErrorType`の具体的な名前は、使用しているAmplifyのバージョンやドキュメンテーションによって異なるかもしれませんので、適切なエラータイプの名前に置き換える必要があるかもしれません。

---
