# Error Conversion Handling

Date: 2024-05-15

---

## 👤 User
*2024-05-15 13:50:49*

以下のエラーになった
Initializer 'init(_:bufferingPolicy:_:)' requires the types 'AppError' and 'any Error' be equivalent

import Foundation // URL
import Combine
import WhisperKit

final class TranscriptionDriver {
//    private let isRecordingSubject = PassthroughSubject&lt;Bool, Never&gt;()
//    var isRecordingPublisher: AnyPublisher&lt;Bool, Never&gt; {
//        isRecordingSubject.eraseToAnyPublisher()
//    }
//
//    private var transcription = "音声をテキストに変換して表示します。"
//    
    func transcribe(fileUrl: URL) async throws -&gt; AsyncThrowingStream&lt;String, AppError&gt; {
        AsyncThrowingStream { continuation in
            Task {
                do {
                    let whisper = try await WhisperKit()
                    if let result = try await whisper.transcribe(audioPath: fileUrl.path,decodeOptions:DecodingOptions.init(language: "ja"))?.text {
                        continuation.yield(result)
                    } else {
                        continuation.yield("トランスクリプションを取得できませんでした。")
                    }
                    continuation.finish()
                } catch {
                    continuation.finish(throwing: error.toAppError)
                }
            }
        }
    }
}

---

## 🤖 Assistant
*2024-05-15 13:50:58*

エラーが発生する原因は、`AsyncThrowingStream`に渡すエラーの型が`AppError`であり、`catch`ブロックで捕捉されるエラーの型が一般的な`Error`であることです。これにより、型の不一致が発生します。

この問題を解決するためには、捕捉した一般的な`Error`を`AppError`に変換する必要があります。以下に修正例を示します。

まず、`Error`型を`AppError`型に変換するための`toAppError`メソッドが定義されていることを確認してください。例えば：

```swift
extension Error {
    var toAppError: AppError {
        // Error型からAppError型への変換ロジックをここに実装する
        return AppError.generalError(self)
    }
}
```

そして、`transcribe`メソッド内でキャッチしたエラーを`AppError`に変換して`continuation.finish(throwing:)`に渡すようにします：

```swift
import Foundation
import Combine
import WhisperKit

// AppErrorの定義があることを前提とします。
enum AppError: Error {
    case generalError(Error)
    // 他のエラーケースも定義する
}

final class TranscriptionDriver {
    func transcribe(fileUrl: URL) async throws -> AsyncThrowingStream<String, AppError> {
        AsyncThrowingStream { continuation in
            Task {
                do {
                    let whisper = try await WhisperKit()
                    if let result = try await whisper.transcribe(audioPath: fileUrl.path, decodeOptions: DecodingOptions(language: "ja"))?.text {
                        continuation.yield(result)
                    } else {
                        continuation.yield("トランスクリプションを取得できませんでした。")
                    }
                    continuation.finish()
                } catch {
                    continuation.finish(throwing: error.toAppError)
                }
            }
        }
    }
}
```

このようにすることで、`AsyncThrowingStream`のエラー型`AppError`と、キャッチしたエラーの型が一致し、エラーが解消されます。

---

## 👤 User
*2024-05-15 13:51:31*

すでにtoAppErrorは定義しているんだ

public extension Error {
    var toAppError: AppError {
        switch self {
        case let appError as AppError:
            appError
        default:
            .customError(String(describing: self))
        }
    }
}

---

## 🤖 Assistant
*2024-05-15 13:51:39*

`toAppError`がすでに定義されているので、それを利用してエラーを適切に変換するコードに問題はないようです。しかし、エラーを`toAppError`メソッドを使って`AppError`に変換する際に、スイッチケースの各分岐で`return`が欠けているようです。修正後のコードは以下の通りです。

まず、`toAppError`メソッドを以下のように修正します：

```swift
public extension Error {
    var toAppError: AppError {
        switch self {
        case let appError as AppError:
            return appError
        default:
            return .customError(String(describing: self))
        }
    }
}
```

そして、`transcribe`メソッド内でキャッチしたエラーを`AppError`に変換して`continuation.finish(throwing:)`に渡すようにします：

```swift
import Foundation
import Combine
import WhisperKit

enum AppError: Error {
    case customError(String)
    // 他のエラーケースも定義する
}

final class TranscriptionDriver {
    func transcribe(fileUrl: URL) async throws -> AsyncThrowingStream<String, AppError> {
        AsyncThrowingStream { continuation in
            Task {
                do {
                    let whisper = try await WhisperKit()
                    if let result = try await whisper.transcribe(audioPath: fileUrl.path, decodeOptions: DecodingOptions(language: "ja"))?.text {
                        continuation.yield(result)
                    } else {
                        continuation.yield("トランスクリプションを取得できませんでした。")
                    }
                    continuation.finish()
                } catch {
                    continuation.finish(throwing: error.toAppError)
                }
            }
        }
    }
}
```

この修正により、`toAppError`が適切に`AppError`を返すようになり、`AsyncThrowingStream`のエラー型`AppError`との整合性が保たれます。

---

## 👤 User
*2024-05-15 13:51:48*

それもやっている

---

## 🤖 Assistant
*2024-05-15 13:52:04*

すでにその修正がされている場合、`AppError`と`Error`の型不一致の原因が他にある可能性があります。`AsyncThrowingStream`を正しく初期化しているか、`AppError`の型が一致しているか確認しましょう。

以下のコードは、最初のコードから完全な動作例を示しています：

```swift
import Foundation
import Combine
import WhisperKit

enum AppError: Error {
    case customError(String)
    // 他のエラーケースも定義する
}

public extension Error {
    var toAppError: AppError {
        switch self {
        case let appError as AppError:
            return appError
        default:
            return .customError(String(describing: self))
        }
    }
}

final class TranscriptionDriver {
    func transcribe(fileUrl: URL) async throws -> AsyncThrowingStream<String, AppError> {
        AsyncThrowingStream { continuation in
            Task {
                do {
                    let whisper = try await WhisperKit()
                    if let result = try await whisper.transcribe(audioPath: fileUrl.path, decodeOptions: DecodingOptions(language: "ja"))?.text {
                        continuation.yield(result)
                    } else {
                        continuation.yield("トランスクリプションを取得できませんでした。")
                    }
                    continuation.finish()
                } catch {
                    continuation.finish(throwing: error.toAppError)
                }
            }
        }
    }
}
```

以下の点を再確認してください：

1. **`AppError`の定義**: `AppError`が`Error`プロトコルに準拠していること。
2. **`toAppError`の実装**: `toAppError`メソッドが正しくエラーを変換していること。
3. **`AsyncThrowingStream`の初期化**: `AsyncThrowingStream`の初期化が正しく行われていること。

エラーがまだ解消されない場合、`AsyncThrowingStream`の初期化や他の部分での型の扱いに問題があるかもしれません。以下にもう一度`transcribe`メソッドを含む全体のコードを再掲します。

```swift
import Foundation
import Combine
import WhisperKit

enum AppError: Error {
    case customError(String)
    // 他のエラーケースも定義する
}

public extension Error {
    var toAppError: AppError {
        switch self {
        case let appError as AppError:
            return appError
        default:
            return .customError(String(describing: self))
        }
    }
}

final class TranscriptionDriver {
    func transcribe(fileUrl: URL) async throws -> AsyncThrowingStream<String, AppError> {
        AsyncThrowingStream { continuation in
            Task {
                do {
                    let whisper = try await WhisperKit()
                    if let result = try await whisper.transcribe(audioPath: fileUrl.path, decodeOptions: DecodingOptions(language: "ja"))?.text {
                        continuation.yield(result)
                    } else {
                        continuation.yield("トランスクリプションを取得できませんでした。")
                    }
                    continuation.finish()
                } catch {
                    continuation.finish(throwing: error.toAppError)
                }
            }
        }
    }
}
```

もしまだ問題が解決しない場合、どの行でエラーが発生しているかを教えていただければ、より具体的なサポートができるかもしれません。

---

## 👤 User
*2024-05-15 13:53:03*

エラー文のbufferingPolicyの記述が必要なのかもしれない

---

## 🤖 Assistant
*2024-05-15 13:53:15*

`AsyncThrowingStream`のイニシャライザには、バッファリングポリシーを指定するオプションがあります。バッファリングポリシーを明示的に指定してみましょう。

以下に修正したコードを示します：

```swift
import Foundation
import Combine
import WhisperKit

enum AppError: Error {
    case customError(String)
    // 他のエラーケースも定義する
}

public extension Error {
    var toAppError: AppError {
        switch self {
        case let appError as AppError:
            return appError
        default:
            return .customError(String(describing: self))
        }
    }
}

final class TranscriptionDriver {
    func transcribe(fileUrl: URL) async throws -> AsyncThrowingStream<String, AppError> {
        AsyncThrowingStream { continuation in
            Task {
                do {
                    let whisper = try await WhisperKit()
                    if let result = try await whisper.transcribe(audioPath: fileUrl.path, decodeOptions: DecodingOptions(language: "ja"))?.text {
                        continuation.yield(result)
                    } else {
                        continuation.yield("トランスクリプションを取得できませんでした。")
                    }
                    continuation.finish()
                } catch {
                    continuation.finish(throwing: error.toAppError)
                }
            }
        }
    }
}
```

次に、`bufferingPolicy`を指定した形で修正したコードを示します：

```swift
import Foundation
import Combine
import WhisperKit

enum AppError: Error {
    case customError(String)
    // 他のエラーケースも定義する
}

public extension Error {
    var toAppError: AppError {
        switch self {
        case let appError as AppError:
            return appError
        default:
            return .customError(String(describing: self))
        }
    }
}

final class TranscriptionDriver {
    func transcribe(fileUrl: URL) async throws -> AsyncThrowingStream<String, AppError> {
        AsyncThrowingStream(bufferingPolicy: .unbounded) { continuation in
            Task {
                do {
                    let whisper = try await WhisperKit()
                    if let result = try await whisper.transcribe(audioPath: fileUrl.path, decodeOptions: DecodingOptions(language: "ja"))?.text {
                        continuation.yield(result)
                    } else {
                        continuation.yield("トランスクリプションを取得できませんでした。")
                    }
                    continuation.finish()
                } catch {
                    continuation.finish(throwing: error.toAppError)
                }
            }
        }
    }
}
```

この修正により、`AsyncThrowingStream`のイニシャライザに`bufferingPolicy`を指定しています。これで、エラーが解消されるはずです。

---
