# エラーハンドリング改善案

Date: 2025-01-15

---

## 👤 User
*2025-01-15 20:06:05*

うまくエラーハンドリングできていないキャッチブロックに行ってほしい

@riverpod
class RequestCodeNotifier extends _$RequestCodeNotifier {
  @override
  Future&lt;String?&gt; build() async =&gt; null;

  Future&lt;void&gt; requestCode(String email) async {
    state = const AsyncValue.loading();
    try {
      final api = await ref.watch(authApiProvider.future);
      final response = await api.authControllerSendCode(
        // AuthEamilDTO(email: email),
        // TODO: Remove this hard-coded email
        AuthEamilDTO(email: 'user1@example.com'),
      );
      throw Exception(response.data.toString());
      debugPrint('Response Body: ${response.data}');
      debugPrint('Response Body.data: ${response.data?.data}');

      if (response.data?.code == -1) {
        debugPrint('Response Body.code: ${response.data?.code}');
        debugPrint(
          'Response Body.errorMessage: ${response.data?.errorMessage}',
        );
        throw Exception(response.data.toString());
      }

      state = AsyncValue.data(response.data?.data);
    } on Exception catch (e, stackTrace) {
      debugPrint('Error: $e');
      debugPrint('StackTrace: $stackTrace');
      state = AsyncValue.error(e, stackTrace);
    }
  }
}

Future&lt;void&gt; onTapRerequestCode() async {
      try {
        await ref.read(requestCodeNotifierProvider.notifier).requestCode(email);

        if (context.mounted) {
          ScaffoldMessenger.of(context).showSnackBar(
            SnackBar(
              content: const Text(
                'Verification code sent to SNPIT app.\n'
                'Please open the SNPIT app.',
              ),
              action: SnackBarAction(
                label: 'Open',
                onPressed: () {
                  openSnapitApp(context);
                },
              ),
            ),
          );
        }
      } on Exception catch (error) {
        if (context.mounted) {
          ScaffoldMessenger.of(context).showSnackBar(
            SnackBar(content: Text('Failed to request code: $error')),
          );
        }
      }
    }

---

## 🤖 Assistant
*2025-01-15 20:06:38*

現在のコードを見ると、`RequestCodeNotifier`内の`try-catch`ブロックでエラーハンドリングが行われており、その後で`onTapRerequestCode`内でも`try-catch`ブロックを使ってエラーハンドリングをしています。ただし、以下のいくつかのポイントにより、エラーが期待通りにキャッチされない可能性があります。

### 問題点の可能性
1. **エラースロー箇所の重複**  
   `requestCode`メソッド内で何度も`throw Exception`を使用しており、特に不要な場所でスローされているため、エラー処理が意図しない挙動をする場合があります。

2. **`AsyncValue.error`の使用による二重エラーハンドリング**  
   `RequestCodeNotifier`で`AsyncValue.error`をセットしていますが、`onTapRerequestCode`内の`try-catch`はそのエラーを直接取得することはありません。

3. **リフレクションエラー**  
   `ref.watch(authApiProvider.future)`が正しく機能しない、または非同期処理のタイミングでエラーが発生する可能性があります。

---

### 改善案

以下のコードは、エラーハンドリングを簡素化し、エラー発生時にキャッチブロックへ確実に到達するようにするためのリファクタリングです。

#### リファクタリング後のコード

```dart
@riverpod
class RequestCodeNotifier extends _$RequestCodeNotifier {
  @override
  Future<String?> build() async => null;

  Future<void> requestCode(String email) async {
    state = const AsyncValue.loading(); // 状態をローディングに更新
    try {
      final api = await ref.watch(authApiProvider.future); // APIプロバイダの読み取り
      final response = await api.authControllerSendCode(
        AuthEamilDTO(email: email),
      );

      // レスポンスがエラーコードを含む場合は例外をスロー
      if (response.data?.code != 0) {
        throw Exception(response.data?.errorMessage ?? 'Unknown error occurred');
      }

      // 成功時の処理
      state = AsyncValue.data(response.data?.data);
    } catch (e, stackTrace) {
      // エラー発生時の状態を更新
      state = AsyncValue.error(e, stackTrace);
      rethrow; // 呼び出し元のtry-catchへエラーを伝搬
    }
  }
}

Future<void> onTapRerequestCode(BuildContext context, String email) async {
  try {
    await ref.read(requestCodeNotifierProvider.notifier).requestCode(email);

    if (context.mounted) {
      ScaffoldMessenger.of(context).showSnackBar(
        SnackBar(
          content: const Text(
            'Verification code sent to SNPIT app.\n'
            'Please open the SNPIT app.',
          ),
          action: SnackBarAction(
            label: 'Open',
            onPressed: () {
              openSnapitApp(context);
            },
          ),
        ),
      );
    }
  } catch (e) {
    if (context.mounted) {
      ScaffoldMessenger.of(context).showSnackBar(
        SnackBar(content: Text('Failed to request code: $e')),
      );
    }
  }
}
```

---

### 改善内容

1. **重複した`throw Exception`の削除**  
   必要な箇所でのみ例外をスローすることで、エラーハンドリングの複雑さを軽減しました。

2. **`rethrow`の使用**  
   `RequestCodeNotifier`内でキャッチした例外を再スローして、呼び出し元の`onTapRerequestCode`の`catch`ブロックで処理できるようにしました。

3. **エラーメッセージの明示**  
   レスポンスの`errorMessage`が存在する場合はそれを、存在しない場合は`Unknown error occurred`をスローすることで、デバッグがしやすくなりました。

4. **状態管理の明確化**  
   成功時とエラー時の`AsyncValue`の更新を適切に行い、UIが正確に反映されるようにしました。

---

### テスト
- **成功時**  
   メールが正しく送信され、スナックバーで通知が表示されることを確認します。
- **エラー時**  
   例外がキャッチブロックへ到達し、適切なエラーメッセージが表示されることを確認します。

---

## 👤 User
*2025-01-15 20:07:12*

よくわかっていないのが rethrow をするとできなくなることってあるの？

---

## 🤖 Assistant
*2025-01-15 20:07:51*

`rethrow` を使う場合に制限される点や注意が必要な点は以下の通りです。`rethrow` 自体は便利ですが、特定の状況では期待した動作が得られない可能性があるため、慎重に使う必要があります。

---

## **1. `rethrow` はキャッチした例外しかスローできない**
`rethrow` は `catch` ブロック内で捕まえた例外をそのまま再スローする機能です。以下の点に注意してください：

- **新しい例外をスローすることはできない**
  ```dart
  try {
    // Some code that might throw an exception
  } catch (e) {
    rethrow; // ここで e をそのまま再スロー
  }
  ```

  ただし、新しい例外をスローする場合は `throw` を使う必要があります：
  ```dart
  try {
    // Some code that might throw an exception
  } catch (e) {
    throw Exception('New exception: $e'); // 新しい例外を生成してスロー
  }
  ```

  **結果**:  
  `rethrow` は、元の例外を加工せず再利用する場合にのみ使えます。

---

## **2. 呼び出し元で適切にキャッチしないと例外がアプリ全体に伝播する**
`rethrow` された例外が上位の呼び出し元でキャッチされない場合、例外はアプリ全体に伝播してクラッシュの原因になります。

```dart
void someFunction() {
  try {
    throw Exception('Error occurred');
  } catch (e) {
    rethrow; // 上位でキャッチされなければアプリがクラッシュ
  }
}

void main() {
  someFunction(); // キャッチしないと例外が伝播
}
```

解決策として、呼び出し元で適切に例外をキャッチする必要があります：
```dart
void main() {
  try {
    someFunction();
  } catch (e) {
    print('Caught exception: $e'); // アプリのクラッシュを防ぐ
  }
}
```

---

## **3. スタックトレースが変わらない**
`rethrow` を使用すると、スタックトレースは元の例外のものが維持されます。これは通常はメリットですが、例外を加工して新しい情報を追加する必要がある場合には不都合です。

例：
```dart
try {
  throw Exception('Original error');
} catch (e, stackTrace) {
  print(stackTrace); // 元のスタックトレースを表示
  rethrow;
}
```

**新しい情報を追加したい場合は、例外を再生成してスローする必要があります：**
```dart
try {
  throw Exception('Original error');
} catch (e, stackTrace) {
  throw Exception('Additional context: $e');
}
```

---

## **4. 非同期処理との組み合わせ**
非同期処理で例外を再スローするとき、`Future` のエラーハンドリングに注意が必要です。例えば、非同期関数内で例外が発生した場合、その例外は通常 `Future` を通じて返されます。

例：
```dart
Future<void> asyncFunction() async {
  try {
    throw Exception('Error in async function');
  } catch (e) {
    rethrow; // 呼び出し元でキャッチする必要あり
  }
}

void main() async {
  try {
    await asyncFunction();
  } catch (e) {
    print('Caught exception: $e');
  }
}
```

**注意点:**  
非同期処理の場合、`rethrow` を使っても呼び出し元が `await` していないと例外をキャッチできずにスルーされることがあります。

---

## **`rethrow` を使うべき場合と使わないべき場合**
### **使うべき場合**
- 元の例外をそのまま呼び出し元に伝えたいとき。
- エラーハンドリングを呼び出し元に任せたいとき。
- スタックトレースを維持してデバッグを容易にしたいとき。

### **使わないべき場合**
- 例外に新しい情報や文脈を追加したいとき。
- 呼び出し元が例外をキャッチしない場合にクラッシュが許容されないとき。

---

## **まとめ**
`rethrow` を使うと例外の伝播が簡潔になりますが、その性質上、**元の例外をそのまま伝える**というシンプルな使い方に向いています。必要に応じて例外に追加情報を加える場合や、スタックトレースを新たにリセットする必要がある場合は、`throw` を使うほうが柔軟です。

明確な目的に応じて、`throw` と `rethrow` を使い分けることが重要です！

---

## 👤 User
*2025-01-15 20:09:19*

この手のNotifierはrethrowするのが無難なのかな？

import 'package:flutter/foundation.dart';
import 'package:riverpod_annotation/riverpod_annotation.dart';
import 'package:snpit_guild_app/infrastructure/snapit_guild_api/snapit_guild_api.openapi.dart';
import 'package:snpit_guild_app/presentation/providers/api_client/api_provider.dart';

part 'request_code.g.dart';

@riverpod
class RequestCodeNotifier extends _$RequestCodeNotifier {
  @override
  Future&lt;String?&gt; build() async =&gt; null;

  Future&lt;void&gt; requestCode(String email) async {
    state = const AsyncValue.loading();
    try {
      final api = await ref.watch(authApiProvider.future);
      final response = await api.authControllerSendCode(
        // AuthEamilDTO(email: email),
        // TODO: Remove this hard-coded email
        AuthEamilDTO(email: 'user1@example.com'),
      );
      throw Exception(response.data.toString());
      debugPrint('Response Body: ${response.data}');
      debugPrint('Response Body.data: ${response.data?.data}');

      if (response.data?.code == -1) {
        debugPrint('Response Body.code: ${response.data?.code}');
        debugPrint(
          'Response Body.errorMessage: ${response.data?.errorMessage}',
        );
        throw Exception(response.data.toString());
      }

      state = AsyncValue.data(response.data?.data);
    } on Exception catch (e, stackTrace) {
      debugPrint('Error: $e');
      debugPrint('StackTrace: $stackTrace');
      state = AsyncValue.error(e, stackTrace);
      rethrow;
    }
  }
}

---

## 🤖 Assistant
*2025-01-15 20:10:16*

このような `Notifier` クラスで `rethrow` を使用するかどうかは、以下の設計方針やユースケースに依存します。

---

## **`rethrow` を使うことのメリット**

1. **呼び出し元で詳細なエラー処理を可能にする**  
   `rethrow` を使うと、例外を呼び出し元に伝播させるため、呼び出し元で独自のエラーハンドリングロジックを追加できます。例えば、UI でスナックバーを表示する処理を行いたい場合や、特定のエラーに応じたリトライ処理を行いたい場合に便利です。

2. **スタックトレースの維持**  
   元のスタックトレースが保持されるため、デバッグ時にどこで例外が発生したのかが分かりやすくなります。

---

## **`rethrow` を使う際の注意点**

1. **二重ハンドリングのリスク**  
   `Notifier` 内で `AsyncValue.error` をセットしている場合、呼び出し元でも同じ例外がキャッチされて二重でエラーハンドリングを行ってしまう可能性があります。これにより、コードが複雑化することがあります。

2. **例外が伝播しすぎる**  
   呼び出し元が例外をキャッチしない場合、例外がアプリ全体に伝播し、クラッシュの原因になることがあります。

---

## **`rethrow` を使うべきかどうかの判断基準**

### **`rethrow` を使うべき場合**
- **例外を呼び出し元で処理する必要がある場合**
  - 呼び出し元で例外に応じた振る舞いをカスタマイズする。
  - 例外の詳細な情報を呼び出し元で活用したい。
- **デバッグ時に例外の発生箇所を詳細に知りたい場合**
  - スタックトレースを保持することで、例外の発生元を追跡しやすくする。

### **`rethrow` を避けるべき場合**
- **`Notifier` でエラーを完結させたい場合**
  - 例外を `AsyncValue.error` に設定して、UI 側でその状態を直接監視する形にしたい場合。
- **例外を加工して別の形式で扱いたい場合**
  - 例外にコンテキストを追加する必要がある場合は、`throw` を使って新しい例外をスローする方が適切です。

---

## **代替案：`rethrow` を使わない設計**

`Notifier` 内でエラー処理を完結させる場合は、`rethrow` を使わずに以下のように実装します：

```dart
@riverpod
class RequestCodeNotifier extends _$RequestCodeNotifier {
  @override
  Future<String?> build() async => null;

  Future<void> requestCode(String email) async {
    state = const AsyncValue.loading();
    try {
      final api = await ref.watch(authApiProvider.future);
      final response = await api.authControllerSendCode(
        AuthEamilDTO(email: email),
      );

      if (response.data?.code == -1) {
        throw Exception(response.data?.errorMessage ?? 'Unknown error');
      }

      state = AsyncValue.data(response.data?.data);
    } catch (e, stackTrace) {
      // エラーを AsyncValue にセットして、呼び出し元に伝播しない
      state = AsyncValue.error(e, stackTrace);
    }
  }
}
```

---

## **`rethrow` を使う場合の設計例**

呼び出し元で例外を処理させたい場合は、以下のように `rethrow` を利用します：

```dart
@riverpod
class RequestCodeNotifier extends _$RequestCodeNotifier {
  @override
  Future<String?> build() async => null;

  Future<void> requestCode(String email) async {
    state = const AsyncValue.loading();
    try {
      final api = await ref.watch(authApiProvider.future);
      final response = await api.authControllerSendCode(
        AuthEamilDTO(email: email),
      );

      if (response.data?.code == -1) {
        throw Exception(response.data?.errorMessage ?? 'Unknown error');
      }

      state = AsyncValue.data(response.data?.data);
    } catch (e, stackTrace) {
      state = AsyncValue.error(e, stackTrace); // 状態は更新
      rethrow; // 例外を呼び出し元に伝播
    }
  }
}
```

呼び出し元で例外を処理：

```dart
Future<void> handleRequestCode(BuildContext context, String email) async {
  try {
    await ref.read(requestCodeNotifierProvider.notifier).requestCode(email);
    ScaffoldMessenger.of(context).showSnackBar(
      const SnackBar(content: Text('Code sent successfully')),
    );
  } catch (e) {
    ScaffoldMessenger.of(context).showSnackBar(
      SnackBar(content: Text('Failed to send code: $e')),
    );
  }
}
```

---

## **結論**

### **`rethrow` を使うべき場合**
- 呼び出し元で例外を処理したい場合。

### **`rethrow` を避けるべき場合**
- 例外を `Notifier` 内で完全に処理する場合。
- 状態管理 (`AsyncValue`) にエラーを反映するだけで十分な場合。

**「Notifier の責務」をどこまでにするか**で決めるのが最適です。

---

## 👤 User
*2025-01-15 20:10:35*

AsyncValue.error の定義はよくする。
UI上でどうすべきかの判断をしたい。
UIではエラーを出すだけで、try catch でスナックバーのようなすみわけがいいのかな？

---

## 🤖 Assistant
*2025-01-15 20:11:33*

`AsyncValue.error` を定義して UI 上でエラー表示を行う場合と、`try-catch` を使って直接スナックバーのようなエラー通知を行う場合には、それぞれ適切なユースケースがあります。その「住み分け」を明確にすることで、責務を分離しつつ、柔軟なエラー処理が可能になります。

以下で、どのように使い分けるべきかを解説します。

---

## **`AsyncValue.error` の役割**

`AsyncValue.error` は **状態管理とエラー情報の伝搬** に特化しています。  
これにより、以下のような特徴があります：

### **特徴**
1. **UI レベルでエラーを簡単に表示**  
   状態が `AsyncValue.error` の場合に、専用の UI（例えばエラーメッセージや再試行ボタン）を表示できます。

2. **非同期操作の状態を一元管理**  
   `loading`、`data`、`error` の 3 状態を統一的に扱えるため、UI ロジックが簡潔になります。

3. **呼び出し元でエラーの詳細を考慮しない**  
   エラーの表示方法が `AsyncValue` を介して一貫するため、呼び出し元で例外処理を行う必要が少なくなります。

---

## **`try-catch` でスナックバーを表示する役割**

`try-catch` を使ったエラー処理は、**ユーザー通知や特定のアクションに基づいたエラー通知**に適しています。

### **特徴**
1. **即時通知が可能**  
   操作後にユーザーに即座に通知（スナックバーなど）を表示したい場合に有効です。

2. **カスタム処理に対応**  
   エラーの種類によって異なる処理（例: 特定のエラー時のみリトライやナビゲーションを実行）を実行できます。

3. **補完的な役割**  
   `AsyncValue.error` を利用するのが適さない、限定的なエラー通知に使えます。

---

## **具体的な住み分け**

以下の基準で `AsyncValue.error` と `try-catch` を住み分けると、より直感的で責務が分離された設計になります。

### **1. UI 表示で完結する場合：`AsyncValue.error`**
- 画面上でエラーを視覚的に表示する必要がある場合。
- 再試行ボタンを提供したい場合。

#### 実装例
```dart
Widget build(BuildContext context, WidgetRef ref) {
  final requestCodeState = ref.watch(requestCodeNotifierProvider);

  return requestCodeState.when(
    data: (data) => Text('Success: $data'),
    loading: () => const CircularProgressIndicator(),
    error: (e, stackTrace) => Column(
      children: [
        Text('Error: ${e.toString()}'),
        ElevatedButton(
          onPressed: () {
            ref.read(requestCodeNotifierProvider.notifier).requestCode('email@example.com');
          },
          child: const Text('Retry'),
        ),
      ],
    ),
  );
}
```

### **2. 即時通知が必要な場合：`try-catch`**
- 操作の結果をすぐに通知したい場合（スナックバーなど）。
- 非同期操作に特化したエラーハンドリングが不要な場合。

#### 実装例
```dart
Future<void> onRequestCode(BuildContext context, String email) async {
  try {
    await ref.read(requestCodeNotifierProvider.notifier).requestCode(email);
    ScaffoldMessenger.of(context).showSnackBar(
      const SnackBar(content: Text('Verification code sent successfully')),
    );
  } catch (e) {
    ScaffoldMessenger.of(context).showSnackBar(
      SnackBar(content: Text('Failed to send verification code: $e')),
    );
  }
}
```

---

## **住み分けのフロー**

1. **非同期状態を UI 上で管理したいか？**  
   - **はい** → `AsyncValue.error` を使う。
   - **いいえ** → 次に進む。

2. **操作後に即座に通知が必要か？**  
   - **はい** → `try-catch` を使う。
   - **いいえ** → 状況に応じて `AsyncValue.error` を検討。

---

## **併用する場合のベストプラクティス**

以下のように、`AsyncValue.error` と `try-catch` を併用して、それぞれの責務を分離することも可能です：

1. **非同期処理の状態を UI で管理**  
   → `AsyncValue.error` でエラーメッセージとリトライ機能を提供。

2. **即時通知**  
   → `try-catch` を使い、成功時や失敗時にユーザー通知を実行。

#### 実装例（併用）
```dart
Future<void> onRequestCode(BuildContext context, String email) async {
  try {
    await ref.read(requestCodeNotifierProvider.notifier).requestCode(email);

    // 成功通知
    ScaffoldMessenger.of(context).showSnackBar(
      const SnackBar(content: Text('Verification code sent successfully')),
    );
  } catch (e) {
    // 即時エラー通知
    ScaffoldMessenger.of(context).showSnackBar(
      SnackBar(content: Text('Failed to send verification code: $e')),
    );
  }
}

// UI 側
Widget build(BuildContext context, WidgetRef ref) {
  final requestCodeState = ref.watch(requestCodeNotifierProvider);

  return requestCodeState.when(
    data: (data) => Text('Success: $data'),
    loading: () => const CircularProgressIndicator(),
    error: (e, stackTrace) => Column(
      children: [
        Text('Error: ${e.toString()}'),
        ElevatedButton(
          onPressed: () {
            ref.read(requestCodeNotifierProvider.notifier).requestCode('email@example.com');
          },
          child: const Text('Retry'),
        ),
      ],
    ),
  );
}
```

---

## **まとめ**

- **`AsyncValue.error` の主な役割**: 非同期処理の状態を UI で管理し、エラーメッセージを画面に表示する。
- **`try-catch` の主な役割**: 即時通知や特定のアクションに基づくエラーハンドリングを行う。

住み分けを意識して使うことで、コードの責務が明確になり、保守性が向上します。

---

## 👤 User
*2025-01-15 22:32:44*

re throw しているのにtry を

---
